<?xml version="1.0" encoding="UTF-8"?>
<testng-results ignored="0" total="5" passed="2" failed="3" skipped="0">
  <reporter-output>
  </reporter-output>
  <suite started-at="2019-09-07T06:19:30Z" name="Suite" finished-at="2019-09-07T06:19:30Z" duration-ms="72">
    <groups>
      <group name="regression">
        <method signature="TestNGGroup.logic3()[pri:0, instance:org.test.login.TestNG.TestNGGroup@75db5df9]" name="logic3" class="org.test.login.TestNG.TestNGGroup"/>
      </group> <!-- regression -->
      <group name="smoke">
        <method signature="TestNGGroup.logic1()[pri:0, instance:org.test.login.TestNG.TestNGGroup@75db5df9]" name="logic1" class="org.test.login.TestNG.TestNGGroup"/>
        <method signature="TestNGGroup.logic2()[pri:0, instance:org.test.login.TestNG.TestNGGroup@75db5df9]" name="logic2" class="org.test.login.TestNG.TestNGGroup"/>
      </group> <!-- smoke -->
      <group name="sanity">
        <method signature="TestNGGroup.logic4()[pri:0, instance:org.test.login.TestNG.TestNGGroup@75db5df9]" name="logic4" class="org.test.login.TestNG.TestNGGroup"/>
        <method signature="TestNGGroup.logic5()[pri:0, instance:org.test.login.TestNG.TestNGGroup@75db5df9]" name="logic5" class="org.test.login.TestNG.TestNGGroup"/>
      </group> <!-- sanity -->
    </groups>
    <test started-at="2019-09-07T06:19:30Z" name="Test" finished-at="2019-09-07T06:19:30Z" duration-ms="72">
      <class name="org.test.login.TestNG.TestNGGroup">
        <test-method signature="logic1()[pri:0, instance:org.test.login.TestNG.TestNGGroup@75db5df9]" started-at="2019-09-07T06:19:30Z" name="logic1" finished-at="2019-09-07T06:19:30Z" duration-ms="18" status="FAIL">
          <exception class="java.lang.AssertionError">
            <full-stacktrace>
              <![CDATA[java.lang.AssertionError
at org.junit.Assert.fail(Assert.java:86)
at org.junit.Assert.assertTrue(Assert.java:41)
at org.junit.Assert.assertTrue(Assert.java:52)
at org.test.login.TestNG.TestNGGroup.logic1(TestNGGroup.java:9)
at java.base/jdk.internal.reflect.NativeMethodAccessorImpl.invoke0(Native Method)
at java.base/jdk.internal.reflect.NativeMethodAccessorImpl.invoke(Unknown Source)
at java.base/jdk.internal.reflect.DelegatingMethodAccessorImpl.invoke(Unknown Source)
at java.base/java.lang.reflect.Method.invoke(Unknown Source)
at org.testng.internal.MethodInvocationHelper.invokeMethod(MethodInvocationHelper.java:124)
at org.testng.internal.Invoker.invokeMethod(Invoker.java:583)
at org.testng.internal.Invoker.invokeTestMethod(Invoker.java:719)
at org.testng.internal.Invoker.invokeTestMethods(Invoker.java:989)
at org.testng.internal.TestMethodWorker.invokeTestMethods(TestMethodWorker.java:125)
at org.testng.internal.TestMethodWorker.run(TestMethodWorker.java:109)
at org.testng.TestRunner.privateRun(TestRunner.java:648)
at org.testng.TestRunner.run(TestRunner.java:505)
at org.testng.SuiteRunner.runTest(SuiteRunner.java:455)
at org.testng.SuiteRunner.runSequentially(SuiteRunner.java:450)
at org.testng.SuiteRunner.privateRun(SuiteRunner.java:415)
at org.testng.SuiteRunner.run(SuiteRunner.java:364)
at org.testng.SuiteRunnerWorker.runSuite(SuiteRunnerWorker.java:52)
at org.testng.SuiteRunnerWorker.run(SuiteRunnerWorker.java:84)
at org.testng.TestNG.runSuitesSequentially(TestNG.java:1208)
at org.testng.TestNG.runSuitesLocally(TestNG.java:1137)
at org.testng.TestNG.runSuites(TestNG.java:1049)
at org.testng.TestNG.run(TestNG.java:1017)
at org.testng.remote.AbstractRemoteTestNG.run(AbstractRemoteTestNG.java:132)
at org.testng.remote.RemoteTestNG.initAndRun(RemoteTestNG.java:230)
at org.testng.remote.RemoteTestNG.main(RemoteTestNG.java:76)
]]>
            </full-stacktrace>
          </exception> <!-- java.lang.AssertionError -->
          <reporter-output>
          </reporter-output>
        </test-method> <!-- logic1 -->
        <test-method signature="logic2()[pri:0, instance:org.test.login.TestNG.TestNGGroup@75db5df9]" started-at="2019-09-07T06:19:30Z" name="logic2" finished-at="2019-09-07T06:19:30Z" duration-ms="3" status="FAIL">
          <exception class="java.lang.AssertionError">
            <full-stacktrace>
              <![CDATA[java.lang.AssertionError
at org.junit.Assert.fail(Assert.java:86)
at org.junit.Assert.assertTrue(Assert.java:41)
at org.junit.Assert.assertTrue(Assert.java:52)
at org.test.login.TestNG.TestNGGroup.logic2(TestNGGroup.java:15)
at java.base/jdk.internal.reflect.NativeMethodAccessorImpl.invoke0(Native Method)
at java.base/jdk.internal.reflect.NativeMethodAccessorImpl.invoke(Unknown Source)
at java.base/jdk.internal.reflect.DelegatingMethodAccessorImpl.invoke(Unknown Source)
at java.base/java.lang.reflect.Method.invoke(Unknown Source)
at org.testng.internal.MethodInvocationHelper.invokeMethod(MethodInvocationHelper.java:124)
at org.testng.internal.Invoker.invokeMethod(Invoker.java:583)
at org.testng.internal.Invoker.invokeTestMethod(Invoker.java:719)
at org.testng.internal.Invoker.invokeTestMethods(Invoker.java:989)
at org.testng.internal.TestMethodWorker.invokeTestMethods(TestMethodWorker.java:125)
at org.testng.internal.TestMethodWorker.run(TestMethodWorker.java:109)
at org.testng.TestRunner.privateRun(TestRunner.java:648)
at org.testng.TestRunner.run(TestRunner.java:505)
at org.testng.SuiteRunner.runTest(SuiteRunner.java:455)
at org.testng.SuiteRunner.runSequentially(SuiteRunner.java:450)
at org.testng.SuiteRunner.privateRun(SuiteRunner.java:415)
at org.testng.SuiteRunner.run(SuiteRunner.java:364)
at org.testng.SuiteRunnerWorker.runSuite(SuiteRunnerWorker.java:52)
at org.testng.SuiteRunnerWorker.run(SuiteRunnerWorker.java:84)
at org.testng.TestNG.runSuitesSequentially(TestNG.java:1208)
at org.testng.TestNG.runSuitesLocally(TestNG.java:1137)
at org.testng.TestNG.runSuites(TestNG.java:1049)
at org.testng.TestNG.run(TestNG.java:1017)
at org.testng.remote.AbstractRemoteTestNG.run(AbstractRemoteTestNG.java:132)
at org.testng.remote.RemoteTestNG.initAndRun(RemoteTestNG.java:230)
at org.testng.remote.RemoteTestNG.main(RemoteTestNG.java:76)
]]>
            </full-stacktrace>
          </exception> <!-- java.lang.AssertionError -->
          <reporter-output>
          </reporter-output>
        </test-method> <!-- logic2 -->
        <test-method signature="logic3()[pri:0, instance:org.test.login.TestNG.TestNGGroup@75db5df9]" started-at="2019-09-07T06:19:30Z" name="logic3" finished-at="2019-09-07T06:19:30Z" duration-ms="1" status="PASS">
          <reporter-output>
          </reporter-output>
        </test-method> <!-- logic3 -->
        <test-method signature="logic4()[pri:0, instance:org.test.login.TestNG.TestNGGroup@75db5df9]" started-at="2019-09-07T06:19:30Z" name="logic4" finished-at="2019-09-07T06:19:30Z" duration-ms="2" status="FAIL">
          <exception class="java.lang.AssertionError">
            <full-stacktrace>
              <![CDATA[java.lang.AssertionError
at org.junit.Assert.fail(Assert.java:86)
at org.junit.Assert.assertTrue(Assert.java:41)
at org.junit.Assert.assertTrue(Assert.java:52)
at org.test.login.TestNG.TestNGGroup.logic4(TestNGGroup.java:27)
at java.base/jdk.internal.reflect.NativeMethodAccessorImpl.invoke0(Native Method)
at java.base/jdk.internal.reflect.NativeMethodAccessorImpl.invoke(Unknown Source)
at java.base/jdk.internal.reflect.DelegatingMethodAccessorImpl.invoke(Unknown Source)
at java.base/java.lang.reflect.Method.invoke(Unknown Source)
at org.testng.internal.MethodInvocationHelper.invokeMethod(MethodInvocationHelper.java:124)
at org.testng.internal.Invoker.invokeMethod(Invoker.java:583)
at org.testng.internal.Invoker.invokeTestMethod(Invoker.java:719)
at org.testng.internal.Invoker.invokeTestMethods(Invoker.java:989)
at org.testng.internal.TestMethodWorker.invokeTestMethods(TestMethodWorker.java:125)
at org.testng.internal.TestMethodWorker.run(TestMethodWorker.java:109)
at org.testng.TestRunner.privateRun(TestRunner.java:648)
at org.testng.TestRunner.run(TestRunner.java:505)
at org.testng.SuiteRunner.runTest(SuiteRunner.java:455)
at org.testng.SuiteRunner.runSequentially(SuiteRunner.java:450)
at org.testng.SuiteRunner.privateRun(SuiteRunner.java:415)
at org.testng.SuiteRunner.run(SuiteRunner.java:364)
at org.testng.SuiteRunnerWorker.runSuite(SuiteRunnerWorker.java:52)
at org.testng.SuiteRunnerWorker.run(SuiteRunnerWorker.java:84)
at org.testng.TestNG.runSuitesSequentially(TestNG.java:1208)
at org.testng.TestNG.runSuitesLocally(TestNG.java:1137)
at org.testng.TestNG.runSuites(TestNG.java:1049)
at org.testng.TestNG.run(TestNG.java:1017)
at org.testng.remote.AbstractRemoteTestNG.run(AbstractRemoteTestNG.java:132)
at org.testng.remote.RemoteTestNG.initAndRun(RemoteTestNG.java:230)
at org.testng.remote.RemoteTestNG.main(RemoteTestNG.java:76)
]]>
            </full-stacktrace>
          </exception> <!-- java.lang.AssertionError -->
          <reporter-output>
          </reporter-output>
        </test-method> <!-- logic4 -->
        <test-method signature="logic5()[pri:0, instance:org.test.login.TestNG.TestNGGroup@75db5df9]" started-at="2019-09-07T06:19:30Z" name="logic5" finished-at="2019-09-07T06:19:30Z" duration-ms="1" status="PASS">
          <reporter-output>
          </reporter-output>
        </test-method> <!-- logic5 -->
      </class> <!-- org.test.login.TestNG.TestNGGroup -->
    </test> <!-- Test -->
  </suite> <!-- Suite -->
</testng-results>
